Workbook

Sheet 00_Readme
B4: Financed and Facilitated Emissions Tool v1.0
B5: Emissions calculation tool for banks and investment firms based on the PCAF Methodology framework published 2025.
D8: Designed by Pranav Yathiraj | E8: Date - 02/22/2026
B10: This User Guide & Tool Documentation is designed for the analysts or auditors who will maintain, update, or refresh this model in future reporting cycles.
B11: 1. Data Architecture & Flow | R11: Tab Name | S11: Function | T11: User Action
B12: This tool follows a linear "Engine-to-Dashboard" architecture. To ensure data integrity, follow this update sequence: | R12: 00_ReadMe | S12: Overview & Methodology | T12: Read first to understand the scope and risk definitions.
B13: Step 1: Set the Foundation (Firm Parameters) | R13: 01_Firm_Parameters | S13: Master Lookups & Dropdowns | T13: Update only if bank standards or internal classifications change.
B14: Action: Update the 01_Firm_Parameters tab. | R14: 02_Executive_Summary | S14: Final Audit & ESG Results | T14: Key Output. View total portfolio GHG, WACI, and Risk Overhang here.
B15: Purpose: This controls the global dropdowns and sector mapping logic used across the entire tool. If the bank adds a new asset class or changes its "Risk Sensitivity" thresholds, update them here first to avoid "broken link" errors in the summary tables. | R15: 03_Entity_Master | S15: Bank Financial Data | T15: Input primary loan data, credit limits, and outstanding balances here.
R16: 04_Legal_Entity_Data | S16: External GHG & Valuation | T16: Input client-level emissions data and enterprise/property values here.
B17: Step 2: Financial Refresh (Entity Master) | R17: 05_PCAF_Engine | S17: Calculation Logic | T17: Do Not Edit. This tab automates the attribution and risk math.
B18: Action: Update the 03_Entity_Master list. | R18: 06_Technical_Appendix | S18: Estimation Logic & Proxies | T18: Reference for how "Score 4/5" proxy-based assets were calculated.
B19: Purpose: Input the latest financial data, including Total Commitments and Funded Exposure. This is the source of truth for the Portfolio Weights used in the WACI calculation. | R19: 07_Reconciliation | S19: Audit & Data Integrity | T19: Use to verify that the Engine totals tie back to the Entity Master.
B21: Audit Check: Ensure the "Grand Total" matches the bank’s general ledger before moving to emissions.
B24: Step 3: Emissions & PCAF Data (Legal Entity Data)
B26: Action: Update 04_Legal_Entity_Data.
B28: Purpose: Input client-level primary emissions data where available. This is where you manually improve the Data Quality Rank (1-5). As clients move from "Estimates" to "Verified Disclosures," the Portfolio WACI becomes more reliable.
B31: Step 4: Proxy Verification (Technical Appendix)
B33: Action: Review the 06_Technical_Appendix.
B35: Purpose: Use this if you are calculating emissions for clients who cannot provide data. This tab manages the "Proxy" math (Score 4 and 5).
B37: Analyst Note: Always check this tab when a sector shows a high Carbon Overhang to see if the estimation methodology needs refining.
B40: Step 5: Engine Processing (PCAF Engine)
B42: Action: Verify 05_PCAF_Engine.
B44: Purpose: This is the automated "Black Box." It maps sector names to the emission factors. You generally don't edit this, but you must check it to ensure no "Unmapped" sectors are throwing off the total attribution.
B47: Step 6: Final Review (Executive Summary)
... B65: Data Quality Rank: Confidence level in the reported numbers (The "Audit").

Sheet 01_Executive_Summary
B1: FINANCED EMISSIONS EXECUTIVE SUMMARY
B3: Figures reflect total Financed Greenhouse Gas Emissions aligned with the PCAF Global Standards
B6: Financed Emissions (Total Committed) | G6: Financed Emissions (Outstanding Drawn) | L6: Portfolio Intensity (WACI) | Q6: Data Quality Score
B8: =O40 -> 2.4848115e+08 | D8: MT CO2e | G8: =P40 -> 2.0576146e+08 | I8: MT CO2e | L8: =T92 -> 333.64919 | N8: MT CO2e / $1M | Q8: =O75 -> 2.2666667
B16: Financial Deep Dives | N16: Emission Deep Dives
B19: 1. Sovereign and Sub-Sovereign Debt represents the primary portfolio anchor, accounting for 64.8% of total Deployed Capital ($400B). | N19: 1. The bank has a contractual "Carbon Overhang" of 42.7 Million tCO2​e.
B20: 2. The portfolio has $43.85B in Undrawn Headroom, primarily concentrated in Business Loans ($35B) | N20: 2. If all current credit facilities are utilized, the bank's financed emissions will increase by 21%
B21: 3. Overall portfolio utilization stands at 93% | N21: 3. Primary Risk Driver: Business Loans represent the largest absolute risk, contributing over 42.5 Million tCO2​e to the potential overhang.
B22: 4. Bank's remaining growth capacity tied to traditionally higher credit risk finances, Business Loans, Real Estate, Mortgage, and Tax Equity. | N22: 4. Business Loans and Corporate Bonds represent the largest footprints, contributing to over 86% of firm's financed emissions
N23: 5. Power Generation is the biggest driver of both realized emissions and future carbon emissions for the portfolio
N24: 6. Healthcare and Real Estate portfolios, albeit lower emissions, have the most sensitive to emissions increase
N25: 7. Bank has roughly 21% unrealized emissions and will potentially impact any emission reduction goals that are set.
B28: Table 1 : Total Committed Asset Exposure by Sector | N28: Table 4 : Emissions Ledger by Asset Classes
B30: Sum of Total_Committed ($B) | C30: Asset Classes
B31: Sectors | C31: Business Loan | D31: Commercial Real Estate | E31: Corp. Bond | F31: Mortgages | G31: Project Finance | H31: Sovereign Debt | I31: Tax Equity | J31: Sub-Sovereign Debt | K31: Grand Total | N31: Asset Classes/Products | O31: Total Commitment Footprint MT CO2e | P31: Funded Footprint MT CO2e | Q31: Carbon Overhang | R31: Emission Risk Delta
B32: Agriculture | C32: 5 | E32: 20 | K32: 25 | N32: =B65 -> Business Loan | O32: =SUMIFS(Committed_Emissions[Attributed_Emissions (MT CO2e)], Committed_Emissions[Asset_Class], '01_Executive_Summary'!N32) -> 1.2703253e+08 | P32: =SUMIFS(Funded_Emissions[Attributed_Emissions (MT CO2e)], Funded_Emissions[Asset_Class], '01_Executive_Summary'!N32) -> 84460285 | Q32: =O32-P32 -> 42572242 | R32: =IFERROR(Q32/P32, 0) -> 0.50405042
B33: Financials | C33: 35 | K33: 35 | N33: =B66 -> Commercial Real Estate | O33: =SUMIFS(Committed_Emissions[Attributed_Emissions (MT CO2e)], Committed_Emissions[Asset_Class], '01_Executive_Summary'!N33) -> 1993.4 | P33: =SUMIFS(Funded_Emissions[Attributed_Emissions (MT CO2e)], Funded_Emissions[Asset_Class], '01_Executive_Summary'!N33) -> 1328.9333 | Q33: =O33-P33 -> 664.46667 | R33: =IFERROR(Q33/P33, 0) -> 0.5
B34: Healthcare | C34: 4.5 | K34: 4.5 | N34: =B67 -> Corp. Bond | O34: =SUMIFS(Committed_Emissions[Attributed_Emissions (MT CO2e)], Committed_Emissions[Asset_Class], '01_Executive_Summary'!N34) -> 87073059 | P34: =SUMIFS(Funded_Emissions[Attributed_Emissions (MT CO2e)], Funded_Emissions[Asset_Class], '01_Executive_Summary'!N34) -> 87073059 | Q34: =O34-P34 -> 0 | R34: =IFERROR(Q34/P34, 0) -> 0
B35: Industrials | C35: 20 | K35: 20 | N35: =B68 -> Mortgages | O35: =SUMIFS(Committed_Emissions[Attributed_Emissions (MT CO2e)], Committed_Emissions[Asset_Class], '01_Executive_Summary'!N35) -> 1889.6 | P35: =SUMIFS(Funded_Emissions[Attributed_Emissions (MT CO2e)], Funded_Emissions[Asset_Class], '01_Executive_Summary'!N35) -> 881.81333 | Q35: =O35-P35 -> 1007.7867 | R35: =IFERROR(Q35/P35, 0) -> 1.1428571
B36: IT | E36: 50 | K36: 50 | N36: =B69 -> Project Finance | O36: =SUMIFS(Committed_Emissions[Attributed_Emissions (MT CO2e)], Committed_Emissions[Asset_Class], '01_Executive_Summary'!N36) -> 496688.57 | P36: =SUMIFS(Funded_Emissions[Attributed_Emissions (MT CO2e)], Funded_Emissions[Asset_Class], '01_Executive_Summary'!N36) -> 413907.14 | Q36: =O36-P36 -> 82781.429 | R36: =IFERROR(Q36/P36, 0) -> 0.2
B37: Oil & Gas | C37: 10 | E37: 10 | K37: 20 | N37: =B70 -> Sovereign Debt | O37: =SUMIFS(Committed_Emissions[Attributed_Emissions (MT CO2e)], Committed_Emissions[Asset_Class], '01_Executive_Summary'!N37) -> 27167089 | P37: =SUMIFS(Funded_Emissions[Attributed_Emissions (MT CO2e)], Funded_Emissions[Asset_Class], '01_Executive_Summary'!N37) -> 27167089 | Q37: =O37-P37 -> 0 | R37: =IFERROR(Q37/P37, 0) -> 0
B38: Power Generation | C38: 25 | E38: 35 | K38: 60 | N38: =B71 -> Tax Equity | O38: =SUMIFS(Committed_Emissions[Attributed_Emissions (MT CO2e)], Committed_Emissions[Asset_Class], '01_Executive_Summary'!N38) -> 210000 | P38: =SUMIFS(Funded_Emissions[Attributed_Emissions (MT CO2e)], Funded_Emissions[Asset_Class], '01_Executive_Summary'!N38) -> 147000 | Q38: =O38-P38 -> 63000 | R38: =IFERROR(Q38/P38, 0) -> 0.42857143
B39: Real Estate | D39: 0.3 | F39: 0.75 | K39: 1.05 | N39: =B72 -> Sub-Sovereign Debt | O39: =SUMIFS(Committed_Emissions[Attributed_Emissions (MT CO2e)], Committed_Emissions[Asset_Class], '01_Executive_Summary'!N39) -> 6497906.4 | P39: =SUMIFS(Funded_Emissions[Attributed_Emissions (MT CO2e)], Funded_Emissions[Asset_Class], '01_Executive_Summary'!N39) -> 6497906.4 | Q39: =O39-P39 -> 0 | R39: =IFERROR(Q39/P39, 0) -> 0
B40: Renewables | C40: 5 | G40: 30 | I40: 10 | K40: 45 | N40: Grand Total | O40: =SUM(O32:O39) -> 2.4848115e+08 | P40: =SUM(P32:P39) -> 2.0576146e+08 | Q40: =O40-P40 -> 42719696 | R40: =IFERROR(Q40/P40, 0) -> 0.20761758
B41: Sovereigns | H41: 300 | J41: 100 | K41: 400
B42: Grand Total | C42: 104.5 | D42: 0.3 | E42: 115 | F42: 0.75 | G42: 30 | H42: 300 | I42: 10 | J42: 100 | K42: 660.55
B45: Table 2 : Capital Utilization: Total committed vs Outstanding Drawn
B46: Current Portfolio ($B) | C46: =GETPIVOTDATA("Funded Exposure ($B)",$B$47) -> 616.7 | E46: Unused Commitment ($B) | F46: =GETPIVOTDATA("Total Committments ($B)",$B$47)-GETPIVOTDATA("Funded Exposure ($B)",$B$47) -> 43.85 | N46: Table 5 : Emissions Ledger by Sector
B47: Row Labels | C47: Total Committments ($B) | D47: Funded Exposure ($B) | E47: % of Total Committed | F47: % of Funded Exposure | G47: Sector Utilization Rate | N47: Sector | O47: Total Commitment Footprint MT CO2e | P47: Funded Footprint MT CO2e | Q47: Carbon Overhang | R47: Emission Risk Delta
B48: Agriculture | C48: 25 | D48: 22 | E48: 0.037847249 | F48: 0.035673747 | G48: 0.88 | N48: =B48 -> Agriculture | O48: =SUMIFS(Committed_Emissions[Attributed_Emissions (MT CO2e)], Committed_Emissions[Sector], '01_Executive_Summary'!N48) -> 45684024 | P48: =SUMIFS(Funded_Emissions[Attributed_Emissions (MT CO2e)], Funded_Emissions[Sector], '01_Executive_Summary'!N48) -> 45454337 | Q48: =O48-P48 -> 229687.5 | R48: =IFERROR(Q48/P48, 0) -> 0.0050531482
B49: Financials | C49: 35 | D49: 25 | E49: 0.052986148 | F49: 0.040538349 | G49: 0.71428571 | N49: =B49 -> Financials | O49: =SUMIFS(Committed_Emissions[Attributed_Emissions (MT CO2e)], Committed_Emissions[Sector], '01_Executive_Summary'!N49) -> 89389.308 | P49: =SUMIFS(Funded_Emissions[Attributed_Emissions (MT CO2e)], Funded_Emissions[Sector], '01_Executive_Summary'!N49) -> 63849.506 | Q49: =O49-P49 -> 25539.802 | R49: =IFERROR(Q49/P49, 0) -> 0.4
B50: Healthcare | C50: 4.5 | D50: 2.15 | E50: 0.0068125047 | F50: 0.003486298 | G50: 0.47777778 | N50: =B50 -> Healthcare | O50: =SUMIFS(Committed_Emissions[Attributed_Emissions (MT CO2e)], Committed_Emissions[Sector], '01_Executive_Summary'!N50) -> 82370.232 | P50: =SUMIFS(Funded_Emissions[Attributed_Emissions (MT CO2e)], Funded_Emissions[Sector], '01_Executive_Summary'!N50) -> 39354.666 | Q50: =O50-P50 -> 43015.566 | R50: =IFERROR(Q50/P50, 0) -> 1.0930233
B51: Industrials | C51: 20 | D51: 15 | E51: 0.030277799 | F51: 0.02432301 | G51: 0.75 | N51: =B51 -> Industrials | O51: =SUMIFS(Committed_Emissions[Attributed_Emissions (MT CO2e)], Committed_Emissions[Sector], '01_Executive_Summary'!N51) -> 51698007 | P51: =SUMIFS(Funded_Emissions[Attributed_Emissions (MT CO2e)], Funded_Emissions[Sector], '01_Executive_Summary'!N51) -> 38773505 | Q51: =O51-P51 -> 12924502 | R51: =IFERROR(Q51/P51, 0) -> 0.33333333
B52: IT | C52: 50 | D52: 50 | E52: 0.075694497 | F52: 0.081076699 | G52: 1 | N52: =B52 -> IT | O52: =SUMIFS(Committed_Emissions[Attributed_Emissions (MT CO2e)], Committed_Emissions[Sector], '01_Executive_Summary'!N52) -> 209289.36 | P52: =SUMIFS(Funded_Emissions[Attributed_Emissions (MT CO2e)], Funded_Emissions[Sector], '01_Executive_Summary'!N52) -> 209289.36 | Q52: =O52-P52 -> 0 | R52: =IFERROR(Q52/P52, 0) -> 0
B53: Oil & Gas | C53: 20 | D53: 17 | E53: 0.030277799 | F53: 0.027566078 | G53: 0.85 | N53: =B53 -> Oil & Gas | O53: =SUMIFS(Committed_Emissions[Attributed_Emissions (MT CO2e)], Committed_Emissions[Sector], '01_Executive_Summary'!N53) -> 28031178 | P53: =SUMIFS(Funded_Emissions[Attributed_Emissions (MT CO2e)], Funded_Emissions[Sector], '01_Executive_Summary'!N53) -> 26343732 | Q53: =O53-P53 -> 1687445.7 | R53: =IFERROR(Q53/P53, 0) -> 0.064054921
B54: Power Generation | C54: 60 | D54: 50 | E54: 0.090833396 | F54: 0.081076699 | G54: 0.83333333 | N54: =B54 -> Power Generation | O54: =SUMIFS(Committed_Emissions[Attributed_Emissions (MT CO2e)], Committed_Emissions[Sector], '01_Executive_Summary'!N54) -> 88153328 | P54: =SUMIFS(Funded_Emissions[Attributed_Emissions (MT CO2e)], Funded_Emissions[Sector], '01_Executive_Summary'!N54) -> 60554477 | Q54: =O54-P54 -> 27598852 | R54: =IFERROR(Q54/P54, 0) -> 0.45576898
B55: Real Estate | C55: 1.05 | D55: 0.55 | E55: 0.0015895844 | F55: 0.00089184368 | G55: 0.52380952 | N55: =B55 -> Real Estate | O55: =SUMIFS(Committed_Emissions[Attributed_Emissions (MT CO2e)], Committed_Emissions[Sector], '01_Executive_Summary'!N55) -> 3883 | P55: =SUMIFS(Funded_Emissions[Attributed_Emissions (MT CO2e)], Funded_Emissions[Sector], '01_Executive_Summary'!N55) -> 2210.7467 | Q55: =O55-P55 -> 1672.2533 | R55: =IFERROR(Q55/P55, 0) -> 0.75642015
B56: Renewables | C56: 45 | D56: 35 | E56: 0.068125047 | F56: 0.056753689 | G56: 0.77777778 | N56: =B56 -> Renewables | O56: =SUMIFS(Committed_Emissions[Attributed_Emissions (MT CO2e)], Committed_Emissions[Sector], '01_Executive_Summary'!N56) -> 864688.57 | P56: =SUMIFS(Funded_Emissions[Attributed_Emissions (MT CO2e)], Funded_Emissions[Sector], '01_Executive_Summary'!N56) -> 655707.14 | Q56: =O56-P56 -> 208981.43 | R56: =IFERROR(Q56/P56, 0) -> 0.31871153
B57: Sovereigns | C57: 400 | D57: 400 | E57: 0.60555598 | F57: 0.64861359 | G57: 1 | N57: =B57 -> Sovereigns | O57: =SUMIFS(Committed_Emissions[Attributed_Emissions (MT CO2e)], Committed_Emissions[Sector], '01_Executive_Summary'!N57) -> 33664995 | P57: =SUMIFS(Funded_Emissions[Attributed_Emissions (MT CO2e)], Funded_Emissions[Sector], '01_Executive_Summary'!N57) -> 33664995 | Q57: =O57-P57 -> 0 | R57: =IFERROR(Q57/P57, 0) -> 0
B58: Grand Total | C58: 660.55 | D58: 616.7 | E58: 1 | F58: 1 | G58: 0.93361593 | N58: =B58 -> Grand Total | O58: =SUM(O48:O57) -> 2.4848115e+08 | P58: =SUM(P48:P57) -> 2.0576146e+08 | Q58: =O58-P58 -> 42719696 | R58: =IFERROR(Q58/P58, 0) -> 0.20761758
...

Sheet 02_Firm_Parameters
A2: Table : Asset Classes
A3: Asset_Class | B3: Entity ID
A4: Sovereign Debt | B4: SD
A5: Corp. Bond | B5: CB
A6: Business Loan | B6: Loan
A7: Project Finance | B7: PF
A8: Tax Equity | B8: TE
A9: Commercial Real Estate | B9: CRE
A10: Mortgages | B10: MOR
A11: Sub-Sovereign Debt | B11: SSD
A14: Table : Financial Status
A15: Financial_Status
A16: Active
A17: Inactive
A21: Table : Sectors
A22: Sectors
A23: Agriculture
A24: Financials
A25: Healthcare
A26: Industrials
A27: IT
A28: Oil & Gas
... A41: Equity+Debt

Sheet 03_Entity_Master
A1: Table 6 : Master Asset Exposure Registry
A3: Entity_ID | B3: Legal_Entity_Name | C3: Asset_Class | D3: Sector | E3: Total_Committed ($B) | F3: Outstanding ($B) | G3: Financial_Status
A4: CB_DUK | B4: Duke Energy | C4: Corp. Bond | D4: Power Generation | E4: 35 | F4: 35 | G4: Active
A5: CB_MSFT | B5: Microsoft | C5: Corp. Bond | D5: IT | E5: 50 | F5: 50 | G5: Active
A6: CB_TOT | B6: TotalEnergies | C6: Corp. Bond | D6: Oil & Gas | E6: 10 | F6: 10 | G6: Active
A7: CB_TSN | B7: Tyson Foods | C7: Corp. Bond | D7: Agriculture | E7: 20 | F7: 20 | G7: Active
A8: CRE_Spire | B8: Spire | C8: Commercial Real Estate | D8: Real Estate | E8: 0.3 | F8: 0.2 | G8: Active
A9: Loan_ADANIPOWER | B9: Adani Power | C9: Business Loan | D9: Power Generation | E9: 25 | F9: 15 | G9: Active
A10: Loan_APO | B10: Apollo Hospitals | C10: Business Loan | D10: Healthcare | E10: 4.5 | F10: 2.15 | G10: Active
A11: Loan_CON | B11: Continental Resources | C11: Business Loan | D11: Oil & Gas | E11: 10 | F11: 7 | G11: Active
A12: Loan_ECO | B12: Eco-Startup Alpha | C12: Business Loan | D12: Renewables | E12: 5 | F12: 3 | G12: Active
A13: Loan_FAM | B13: Family Farm LLC | C13: Business Loan | D13: Agriculture | E13: 5 | F13: 2 | G13: Active
A14: Loan_HDB | B14: HDFC Bank | C14: Business Loan | D14: Financials | E14: 35 | F14: 25 | G14: Active
A15: Loan_TAT | B15: Tata Steel | C15: Business Loan | D15: Industrials | E15: 20 | F15: 15 | G15: Active
... A21: TE_REN | B21: ReNew Power | C21: Tax Equity | D21: Renewables | E21: 10 | F21: 7 | G21: Active

Sheet 04_Legal_Entity_Data
A1: Table 6 : Environmental Reference Registry
A3: Entity_ID | B3: Legal_Entity_Name | C3: Asset_Class | D3: Sector | E3: Denominator_Type | F3: Entity_Denominator_Value ($B) | G3: Denominator Data Source | H3: Entity_GHG_Emissions (tCO2e) | I3: GHG Emissions Data Source | J3: Data Quality Rank | K3: Data Quality Description | L3: Notes | R3: Denominator values as of 12/31/2025
A4: TE_REN | B4: ReNew Power | C4: Tax Equity | D4: Renewables | E4: Project Value | F4: 15 | G4: Simulated | H4: 315000 | I4: Estimation | J4: 4 | K4: Estimated using sector average data | L4: Denominator is project value
A5: SSD_USA_CA | B5: State of California | C5: Sub-Sovereign Debt | D5: Sovereigns | E5: GDP | F5: 4296 | G5: https://apps.bea.gov/itable/?ReqID=99&step=1#eyJhcHBpZCI6OTksInN0ZXBzIjpbMSwyOSwyNSwyNiwyNyw0MF0sImRhdGEiOltbIlRhYmxlSWQiLCI1MzIiXSxbIk1ham9yQXJlYUtleSIsIjAiXSxbIkxpbmUiLCIzIl0sWyJTdGF0ZSIsIjAiXSxbIlVuaXRfb2ZfTWVhc3VyZSIsIkxldmVscyJdLFsiTWFwQ29sb3IiLCJCRUFTdGFuZGFyZCJdLFsiblJhbmdlIiwiNSJdLFsiWWVhciIsIjIwMjU6UTMiXSxbIlllYXJCZWdpbiIsIi0xIl0sWyJZZWFyRW5kIiwiLTEiXV19 | H5: 360400000 | I5: https://ww2.arb.ca.gov/ghg-inventory-data | J5: 1 | K5: Reported data Available | L5: Denominator is statewise Q3 GDP (latest available). Nominal GDP used
A6: SSD_IND_MH_MUM | B6: City of Mumbai | C6: Sub-Sovereign Debt | D6: Sovereigns | E6: GDP | F6: 1178 | G6: https://prsindia.org/budgets/states/maharashtra-budget-analysis-2025-26 | H6: 24560000 | I6: https://mcap.mcgm.gov.in/wp-content/uploads/2025/06/English_CB-Report-2025-26_digital.pdf | J6: 1 | K6: Reported data Available | L6: Denominator is GDP with PPP applied. State GSDP available. Mum city ~26% of state. Converted to USD and PPP of 3.8 applied to normalize
A7: SD_DEU | B7: Fed. Republic of Germany | C7: Sovereign Debt | D7: Sovereigns | E7: GDP | F7: 6320 | G7: https://www.imf.org/external/datamapper/PPPGDP@WEO/DEU?zoom=DEU&highlight=DEU | H7: 572320000 | I7: https://ourworldindata.org/profile/co2/germany | J7: 1 | K7: Reported data Available | L7: Denominator is GDP. Include PPP to standardize to USD
A8: PF_NEX | B8: NextEra Energy | C8: Project Finance | D8: Renewables | E8: Project Value | F8: 35 | G8: Simulated | H8: 579470 | I8: Estimation | J8: 4 | K8: Estimated using sector average data | L8: Denominator is project value
A9: MOR_Local_Biz | B9: Local Biz Plaza | C9: Mortgages | D9: Real Estate | E9: Property Value | F9: 1.875 | G9: Simulated | H9: 4724 | I9: Estimation | J9: 4 | K9: Estimated using location specific intensity factor | L9: Denominator is property value
A10: Loan_TAT | B10: Tata Steel | C10: Business Loan | D10: Industrials | E10: EVIC | F10: 35.63 | G10: https://finance.yahoo.com/quote/TATASTEEL.NS/key-statistics/ | H10: 92100000 | I10: https://www.tatasteel.com/media/24907/ghg-assurance-statement.pdf | J10: 1 | K10: Reported data Available | L10: Denominator is EVIC if company is listed
A11: Loan_HDB | B11: HDFC Bank | C11: Business Loan | D11: Financials | E11: EVIC | F11: 232.26 | G11: Market Cap - [https://ng.investing.com/pro/NYSE:HDB/explorer/marketcap](https://ng.investing.com/pro/NYSE:HDB/explorer/marketcap), Borrowing = [https://www.hdfc.bank.in/content/dam/hdfcbankpws/in/en/pdf/financial-results/2025-2026/quarter-3/financial-results-for-the-quarter-and-nine-months-ended-December-31-2025.pdf](https://www.hdfc.bank.in/content/dam/hdfcbankpws/in/en/pdf/financial-results/2025-2026/quarter-3/financial-results-for-the-quarter-and-nine-months-ended-December-31-2025.pdf) | H11: 593187.45 | I11: https://www.bseindia.com/xml-data/corpfiling/AttachHis/f93b8c16-f2e4-49b3-9280-6c399a753158.pdf | J11: 1 | K11: Reported data Available | L11: Denominator is EVIC if company is listed
A12: Loan_FAM | B12: Family Farm LLC | C12: Business Loan | D12: Agriculture | E12: Equity+Debt | F12: 16 | G12: Simulated | H12: =VLOOKUP(A12, '06_Technical_Appendix'!$A:$H, 8, FALSE) -> 1225000 | I12: Simulated | J12: 4 | K12: Estimated using company revenue | L12: Denominator is Total Equity + Debt for privately held companies
A13: Loan_ECO | B13: Eco-Startup Alpha | C13: Business Loan | D13: Renewables | E13: Equity+Debt | F13: 15 | G13: Simulated | H13: 474000 | I13: Simulated | J13: 3 | K13: Estimated using company production | L13: Denominator is Total Equity + Debt for privately held companies
A14: Loan_CON | B14: Continental Resources | C14: Business Loan | D14: Oil & Gas | E14: Equity+Debt | F14: 19.067 | G14: http://edgar.secdatabase.com/792/119312526064403/filing-main.htm#consolidatedbalancesheets | H14: =VLOOKUP(A14, '06_Technical_Appendix'!$A:$H, 8, FALSE) -> 10724842 | I14: Estimation | J14: 4 | K14: Estimated using company revenue | L14: Denominator is Total Equity + Debt for privately held companies
A15: Loan_APO | B15: Apollo Hospitals | C15: Business Loan | D15: Healthcare | E15: EVIC | F15: 12.67 | G15: https://finance.yahoo.com/quote/ADANIPOWER.NS/key-statistics/ | H15: =VLOOKUP(A15, '06_Technical_Appendix'!$A:$H, 8, FALSE) -> 231917.96 | I15: Estimation | J15: 4 | K15: Estimated using company revenue | L15: Denominator is EVIC for loans to listed companies
A16: Loan_ADANIPOWER | B16: Adani Power | C16: Business Loan | D16: Power Generation | E16: EVIC | F16: 40.06 | G16: https://finance.yahoo.com/quote/ADANIPOWER.NS/key-statistics/ | H16: 110561000 | I16: https://connect.adani.com/annual_report/2025/power/ghg-emission-management.html#ghg-head | J16: 2 | K16: Report available but not verified | L16: Denominator is EVIC for loans to listed companies
A17: CRE_Spire | B17: Spire | C17: Commercial Real Estate | D17: Real Estate | E17: Property Value | F17: 1.5 | G17: Simulated | H17: 9967 | I17: Simulated | J17: 2 | K17: Using Average Emission Factors | L17: Denominator is property value
A18: CB_TSN | B18: Tyson Foods | C18: Corp. Bond | D18: Agriculture | E18: EVIC | F18: 29 | G18: https://finance.yahoo.com/quote/TSN/key-statistics/ | H18: ='06_Technical_Appendix'!I17 -> 65686757 | I18: Estimation | J18: 4 | K18: Estimated using sector average data | L18: Denominator is EVIC if company is listed
A19: CB_TOT | B19: TotalEnergies | C19: Corp. Bond | D19: Oil & Gas | E19: EVIC | F19: 201.3 | G19: https://finance.yahoo.com/quote/TTE/key-statistics/ | H19: 451040000 | I19: https://totalenergies.com/system/files/documents/totalenergies_sustainability-climate-2025-progress-report_2025_en.pdf | J19: 1 | K19: Reported data Available | L19: Denominator is EVIC if company is listed
A20: CB_MSFT | B20: Microsoft | C20: Corp. Bond | D20: IT | E20: EVIC | F20: 3713.28 | G20: https://finance.yahoo.com/quote/MSFT/key-statistics/ | H20: 15543000 | I20: https://cdn-dynmedia-1.microsoft.com/is/content/microsoftcorp/microsoft/msc/documents/presentations/CSR/2025-Microsoft-Environmental-Data-Fact-Sheet-PDF.pdf | J20: 1 | K20: Reported data Available | L20: Denominator is EVIC if company is listed
A21: CB_DUK | B21: Duke Energy | C21: Corp. Bond | D21: Power Generation | E21: EVIC | F21: 181.08 | G21: https://finance.yahoo.com/quote/DUK/key-statistics/ | H21: 99108700 | I21: CDP - https://s201.q4cdn.com/583395453/files/doc_downloads/esg-key-documents/2026/FINAL-2025-CDP-Response_Submitted_11_18_2025.pdf | J21: 1 | K21: Reported data Available | L21: Denominator is EVIC if company is listed
A22: Total | F22: =SUM(Table5[Entity_Denominator_Value ($B)]) -> 16342.722 | H22: =SUM(Table5[Entity_GHG_Emissions (tCO2e)]) -> 1.8054776e+09 | J22: =SUBTOTAL(101,Table5[Data Quality Rank]) -> 2.3888889

Sheet 05_PCAF_Engine
A1: Table 4: Financed GHG Inventory for Outstanding Drawn Capital
A3: Entity Details | E3: Attribution Factor Calculation | H3: GHG Emissions Calculations | J3: Checks and Balances
A4: Entity_ID | B4: Legal_Entity_Name | C4: Asset_Class | D4: Sector | E4: Ref_Outstanding ($B) | F4: Ref_Denominator ($B) | G4: Attribute_Factor (%) | H4: GHG Emissions (MT CO2e) | I4: Attributed_Emissions (MT CO2e) | J4: Check_Unit_Alert | K4: Check_Entity_Match | L4: Check_Attribute_Factor
A5: CB_DUK | B5: Duke Energy | C5: Corp. Bond | D5: Power Generation | E5: =_xlfn.XLOOKUP(A5, Entity_Master[Entity_ID], Entity_Master[Outstanding ($B)], "Missing ID") -> 35 | F5: =_xlfn.XLOOKUP(A5, Table5[Entity_ID], Table5[Entity_Denominator_Value ($B)], "Missing ID") -> 181.08 | G5: =E5/F5 -> 0.19328474 | H5: =_xlfn.XLOOKUP(A5, Table5[Entity_ID], Table5[Entity_GHG_Emissions (tCO2e)], "Missing ID") -> 99108700 | I5: =G5*H5 -> 19156199 | J5: =IF(Funded_Emissions[[#This Row],[Attribute_Factor (%)]]< 0.0001,"Check Units!","$ Units OK") -> $ Units OK | K5: =IF(AND(Funded_Emissions[[#This Row],[Entity_ID]]=_xlfn.XLOOKUP(Funded_Emissions[[#This Row],[Entity_ID]],Entity_Master[Entity_ID],Entity_Master[Entity_ID]), Funded_Emissions[[#This Row],[Entity_ID]]=_xlfn.XLOOKUP(Funded_Emissions[[#This Row],[Entity_ID]],Table5[Entity_ID],Table5[Entity_ID])),"✅ Match","❌ ID MISMATCH") -> ✅ Match | L5: =IF(Funded_Emissions[[#This Row],[Attribute_Factor (%)]] > 1, "Check Denominator", "✅ OK") -> ✅ OK
A6: CB_MSFT | B6: Microsoft | C6: Corp. Bond | D6: IT | E6: =_xlfn.XLOOKUP(A6, Entity_Master[Entity_ID], Entity_Master[Outstanding ($B)], "Missing ID") -> 50 | F6: =_xlfn.XLOOKUP(A6, Table5[Entity_ID], Table5[Entity_Denominator_Value ($B)], "Missing ID") -> 3713.28 | G6: =E6/F6 -> 0.013465184 | H6: =_xlfn.XLOOKUP(A6, Table5[Entity_ID], Table5[Entity_GHG_Emissions (tCO2e)], "Missing ID") -> 15543000 | I6: =G6*H6 -> 209289.36 | J6: =IF(Funded_Emissions[[#This Row],[Attribute_Factor (%)]]< 0.0001,"Check Units!","$ Units OK") -> $ Units OK | K6: =IF(AND(Funded_Emissions[[#This Row],[Entity_ID]]=_xlfn.XLOOKUP(Funded_Emissions[[#This Row],[Entity_ID]],Entity_Master[Entity_ID],Entity_Master[Entity_ID]), Funded_Emissions[[#This Row],[Entity_ID]]=_xlfn.XLOOKUP(Funded_Emissions[[#This Row],[Entity_ID]],Table5[Entity_ID],Table5[Entity_ID])),"✅ Match","❌ ID MISMATCH") -> ✅ Match | L6: =IF(Funded_Emissions[[#This Row],[Attribute_Factor (%)]] > 1, "Check Denominator", "✅ OK") -> ✅ OK
A7: CB_TOT | B7: TotalEnergies | C7: Corp. Bond | D7: Oil & Gas | E7: =_xlfn.XLOOKUP(A7, Entity_Master[Entity_ID], Entity_Master[Outstanding ($B)], "Missing ID") -> 10 | F7: =_xlfn.XLOOKUP(A7, Table5[Entity_ID], Table5[Entity_Denominator_Value ($B)], "Missing ID") -> 201.3 | G7: =E7/F7 -> 0.049677099 | H7: =_xlfn.XLOOKUP(A7, Table5[Entity_ID], Table5[Entity_GHG_Emissions (tCO2e)], "Missing ID") -> 451040000 | I7: =G7*H7 -> 22406359 | J7: =IF(Funded_Emissions[[#This Row],[Attribute_Factor (%)]]< 0.0001,"Check Units!","$ Units OK") -> $ Units OK | K7: =IF(AND(Funded_Emissions[[#This Row],[Entity_ID]]=_xlfn.XLOOKUP(Funded_Emissions[[#This Row],[Entity_ID]],Entity_Master[Entity_ID],Entity_Master[Entity_ID]), Funded_Emissions[[#This Row],[Entity_ID]]=_xlfn.XLOOKUP(Funded_Emissions[[#This Row],[Entity_ID]],Table5[Entity_ID],Table5[Entity_ID])),"✅ Match","❌ ID MISMATCH") -> ✅ Match | L7: =IF(Funded_Emissions[[#This Row],[Attribute_Factor (%)]] > 1, "Check Denominator", "✅ OK") -> ✅ OK
A8: CB_TSN | B8: Tyson Foods | C8: Corp. Bond | D8: Agriculture | E8: =_xlfn.XLOOKUP(A8, Entity_Master[Entity_ID], Entity_Master[Outstanding ($B)], "Missing ID") -> 20 | F8: =_xlfn.XLOOKUP(A8, Table5[Entity_ID], Table5[Entity_Denominator_Value ($B)], "Missing ID") -> 29 | G8: =E8/F8 -> 0.68965517 | H8: =_xlfn.XLOOKUP(A8, Table5[Entity_ID], Table5[Entity_GHG_Emissions (tCO2e)], "Missing ID") -> 65686757 | I8: =G8*H8 -> 45301212 | J8: =IF(Funded_Emissions[[#This Row],[Attribute_Factor (%)]]< 0.0001,"Check Units!","$ Units OK") -> $ Units OK | K8: =IF(AND(Funded_Emissions[[#This Row],[Entity_ID]]=_xlfn.XLOOKUP(Funded_Emissions[[#This Row],[Entity_ID]],Entity_Master[Entity_ID],Entity_Master[Entity_ID]), Funded_Emissions[[#This Row],[Entity_ID]]=_xlfn.XLOOKUP(Funded_Emissions[[#This Row],[Entity_ID]],Table5[Entity_ID],Table5[Entity_ID])),"✅ Match","❌ ID MISMATCH") -> ✅ Match | L8: =IF(Funded_Emissions[[#This Row],[Attribute_Factor (%)]] > 1, "Check Denominator", "✅ OK") -> ✅ OK
A9: CRE_Spire | B9: Spire | C9: Commercial Real Estate | D9: Real Estate | E9: =_xlfn.XLOOKUP(A9, Entity_Master[Entity_ID], Entity_Master[Outstanding ($B)], "Missing ID") -> 0.2 | F9: =_xlfn.XLOOKUP(A9, Table5[Entity_ID], Table5[Entity_Denominator_Value ($B)], "Missing ID") -> 1.5 | G9: =E9/F9 -> 0.13333333 | H9: =_xlfn.XLOOKUP(A9, Table5[Entity_ID], Table5[Entity_GHG_Emissions (tCO2e)], "Missing ID") -> 9967 | I9: =G9*H9 -> 1328.9333 | J9: =IF(Funded_Emissions[[#This Row],[Attribute_Factor (%)]]< 0.0001,"Check Units!","$ Units OK") -> $ Units OK | K9: =IF(AND(Funded_Emissions[[#This Row],[Entity_ID]]=_xlfn.XLOOKUP(Funded_Emissions[[#This Row],[Entity_ID]],Entity_Master[Entity_ID],Entity_Master[Entity_ID]), Funded_Emissions[[#This Row],[Entity_ID]]=_xlfn.XLOOKUP(Funded_Emissions[[#This Row],[Entity_ID]],Table5[Entity_ID],Table5[Entity_ID])),"✅ Match","❌ ID MISMATCH") -> ✅ Match | L9: =IF(Funded_Emissions[[#This Row],[Attribute_Factor (%)]] > 1, "Check Denominator", "✅ OK") -> ✅ OK
A10: Loan_ADANIPOWER | B10: Adani Power | C10: Business Loan | D10: Power Generation | E10: =_xlfn.XLOOKUP(A10, Entity_Master[Entity_ID], Entity_Master[Outstanding ($B)], "Missing ID") -> 15 | F10: =_xlfn.XLOOKUP(A10, Table5[Entity_ID], Table5[Entity_Denominator_Value ($B)], "Missing ID") -> 40.06 | G10: =E10/F10 -> 0.37443834 | H10: =_xlfn.XLOOKUP(A10, Table5[Entity_ID], Table5[Entity_GHG_Emissions (tCO2e)], "Missing ID") -> 110561000 | I10: =G10*H10 -> 41398278 | J10: =IF(Funded_Emissions[[#This Row],[Attribute_Factor (%)]]< 0.0001,"Check Units!","$ Units OK") -> $ Units OK | K10: =IF(AND(Funded_Emissions[[#This Row],[Entity_ID]]=_xlfn.XLOOKUP(Funded_Emissions[[#This Row],[Entity_ID]],Entity_Master[Entity_ID],Entity_Master[Entity_ID]), Funded_Emissions[[#This Row],[Entity_ID]]=_xlfn.XLOOKUP(Funded_Emissions[[#This Row],[Entity_ID]],Table5[Entity_ID],Table5[Entity_ID])),"✅ Match","❌ ID MISMATCH") -> ✅ Match | L10: =IF(Funded_Emissions[[#This Row],[Attribute_Factor (%)]] > 1, "Check Denominator", "✅ OK") -> ✅ OK
A11: Loan_APO | B11: Apollo Hospitals | C11: Business Loan | D11: Healthcare | E11: =_xlfn.XLOOKUP(A11, Entity_Master[Entity_ID], Entity_Master[Outstanding ($B)], "Missing ID") -> 2.15 | F11: =_xlfn.XLOOKUP(A11, Table5[Entity_ID], Table5[Entity_Denominator_Value ($B)], "Missing ID") -> 12.67 | G11: =E11/F11 -> 0.16969219 | H11: =_xlfn.XLOOKUP(A11, Table5[Entity_ID], Table5[Entity_GHG_Emissions (tCO2e)], "Missing ID") -> 231917.96 | I11: =G11*H11 -> 39354.666 | J11: =IF(Funded_Emissions[[#This Row],[Attribute_Factor (%)]]< 0.0001,"Check Units!","$ Units OK") -> $ Units OK | K11: =IF(AND(Funded_Emissions[[#This Row],[Entity_ID]]=_xlfn.XLOOKUP(Funded_Emissions[[#This Row],[Entity_ID]],Entity_Master[Entity_ID],Entity_Master[Entity_ID]), Funded_Emissions[[#This Row],[Entity_ID]]=_xlfn.XLOOKUP(Funded_Emissions[[#This Row],[Entity_ID]],Table5[Entity_ID],Table5[Entity_ID])),"✅ Match","❌ ID MISMATCH") -> ✅ Match | L11: =IF(Funded_Emissions[[#This Row],[Attribute_Factor (%)]] > 1, "Check Denominator", "✅ OK") -> ✅ OK
A12: Loan_CON | B12: Continental Resources | C12: Business Loan | D12: Oil & Gas | E12: =_xlfn.XLOOKUP(A12, Entity_Master[Entity_ID], Entity_Master[Outstanding ($B)], "Missing ID") -> 7 | F12: =_xlfn.XLOOKUP(A12, Table5[Entity_ID], Table5[Entity_Denominator_Value ($B)], "Missing ID") -> 19.067 | G12: =E12/F12 -> 0.36712645 | H12: =_xlfn.XLOOKUP(A12, Table5[Entity_ID], Table5[Entity_GHG_Emissions (tCO2e)], "Missing ID") -> 10724842 | I12: =G12*H12 -> 3937373.2 | J12: =IF(Funded_Emissions[[#This Row],[Attribute_Factor (%)]]< 0.0001,"Check Units!","$ Units OK") -> $ Units OK | K12: =IF(AND(Funded_Emissions[[#This Row],[Entity_ID]]=_xlfn.XLOOKUP(Funded_Emissions[[#This Row],[Entity_ID]],Entity_Master[Entity_ID],Entity_Master[Entity_ID]), Funded_Emissions[[#This Row],[Entity_ID]]=_xlfn.XLOOKUP(Funded_Emissions[[#This Row],[Entity_ID]],Table5[Entity_ID],Table5[Entity_ID])),"✅ Match","❌ ID MISMATCH") -> ✅ Match | L12: =IF(Funded_Emissions[[#This Row],[Attribute_Factor (%)]] > 1, "Check Denominator", "✅ OK") -> ✅ OK
A13: Loan_ECO | B13: Eco-Startup Alpha | C13: Business Loan | D13: Renewables | E13: =_xlfn.XLOOKUP(A13, Entity_Master[Entity_ID], Entity_Master[Outstanding ($B)], "Missing ID") -> 3 | F13: =_xlfn.XLOOKUP(A13, Table5[Entity_ID], Table5[Entity_Denominator_Value ($B)], "Missing ID") -> 15 | G13: =E13/F13 -> 0.2 | H13: =_xlfn.XLOOKUP(A13, Table5[Entity_ID], Table5[Entity_GHG_Emissions (tCO2e)], "Missing ID") -> 474000 | I13: =G13*H13 -> 94800 | J13: =IF(Funded_Emissions[[#This Row],[Attribute_Factor (%)]]< 0.0001,"Check Units!","$ Units OK") -> $ Units OK | K13: =IF(AND(Funded_Emissions[[#This Row],[Entity_ID]]=_xlfn.XLOOKUP(Funded_Emissions[[#This Row],[Entity_ID]],Entity_Master[Entity_ID],Entity_Master[Entity_ID]), Funded_Emissions[[#This Row],[Entity_ID]]=_xlfn.XLOOKUP(Funded_Emissions[[#This Row],[Entity_ID]],Table5[Entity_ID],Table5[Entity_ID])),"✅ Match","❌ ID MISMATCH") -> ✅ Match | L13: =IF(Funded_Emissions[[#This Row],[Attribute_Factor (%)]] > 1, "Check Denominator", "✅ OK") -> ✅ OK
A14: Loan_FAM | B14: Family Farm LLC | C14: Business Loan | D14: Agriculture | E14: =_xlfn.XLOOKUP(A14, Entity_Master[Entity_ID], Entity_Master[Outstanding ($B)], "Missing ID") -> 2 | F14: =_xlfn.XLOOKUP(A14, Table5[Entity_ID], Table5[Entity_Denominator_Value ($B)], "Missing ID") -> 16 | G14: =E14/F14 -> 0.125 | H14: =_xlfn.XLOOKUP(A14, Table5[Entity_ID], Table5[Entity_GHG_Emissions (tCO2e)], "Missing ID") -> 1225000 | I14: =G14*H14 -> 153125 | J14: =IF(Funded_Emissions[[#This Row],[Attribute_Factor (%)]]< 0.0001,"Check Units!","$ Units OK") -> $ Units OK | K14: =IF(AND(Funded_Emissions[[#This Row],[Entity_ID]]=_xlfn.XLOOKUP(Funded_Emissions[[#This Row],[Entity_ID]],Entity_Master[Entity_ID],Entity_Master[Entity_ID]), Funded_Emissions[[#This Row],[Entity_ID]]=_xlfn.XLOOKUP(Funded_Emissions[[#This Row],[Entity_ID]],Table5[Entity_ID],Table5[Entity_ID])),"✅ Match","❌ ID MISMATCH") -> ✅ Match | L14: =IF(Funded_Emissions[[#This Row],[Attribute_Factor (%)]] > 1, "Check Denominator", "✅ OK") -> ✅ OK
A15: Loan_HDB | B15: HDFC Bank | C15: Business Loan | D15: Financials | E15: =_xlfn.XLOOKUP(A15, Entity_Master[Entity_ID], Entity_Master[Outstanding ($B)], "Missing ID") -> 25 | F15: =_xlfn.XLOOKUP(A15, Table5[Entity_ID], Table5[Entity_Denominator_Value ($B)], "Missing ID") -> 232.26 | G15: =E15/F15 -> 0.10763799 | H15: =_xlfn.XLOOKUP(A15, Table5[Entity_ID], Table5[Entity_GHG_Emissions (tCO2e)], "Missing ID") -> 593187.45 | I15: =G15*H15 -> 63849.506 | J15: =IF(Funded_Emissions[[#This Row],[Attribute_Factor (%)]]< 0.0001,"Check Units!","$ Units OK") -> $ Units OK | K15: =IF(AND(Funded_Emissions[[#This Row],[Entity_ID]]=_xlfn.XLOOKUP(Funded_Emissions[[#This Row],[Entity_ID]],Entity_Master[Entity_ID],Entity_Master[Entity_ID]), Funded_Emissions[[#This Row],[Entity_ID]]=_xlfn.XLOOKUP(Funded_Emissions[[#This Row],[Entity_ID]],Table5[Entity_ID],Table5[Entity_ID])),"✅ Match","❌ ID MISMATCH") -> ✅ Match | L15: =IF(Funded_Emissions[[#This Row],[Attribute_Factor (%)]] > 1, "Check Denominator", "✅ OK") -> ✅ OK
A16: Loan_TAT | B16: Tata Steel | C16: Business Loan | D16: Industrials | E16: =_xlfn.XLOOKUP(A16, Entity_Master[Entity_ID], Entity_Master[Outstanding ($B)], "Missing ID") -> 15 | F16: =_xlfn.XLOOKUP(A16, Table5[Entity_ID], Table5[Entity_Denominator_Value ($B)], "Missing ID") -> 35.63 | G16: =E16/F16 -> 0.42099354 | H16: =_xlfn.XLOOKUP(A16, Table5[Entity_ID], Table5[Entity_GHG_Emissions (tCO2e)], "Missing ID") -> 92100000 | I16: =G16*H16 -> 38773505 | J16: =IF(Funded_Emissions[[#This Row],[Attribute_Factor (%)]]< 0.0001,"Check Units!","$ Units OK") -> $ Units OK | K16: =IF(AND(Funded_Emissions[[#This Row],[Entity_ID]]=_xlfn.XLOOKUP(Funded_Emissions[[#This Row],[Entity_ID]],Entity_Master[Entity_ID],Entity_Master[Entity_ID]), Funded_Emissions[[#This Row],[Entity_ID]]=_xlfn.XLOOKUP(Funded_Emissions[[#This Row],[Entity_ID]],Table5[Entity_ID],Table5[Entity_ID])),"✅ Match","❌ ID MISMATCH") -> ✅ Match | L16: =IF(Funded_Emissions[[#This Row],[Attribute_Factor (%)]] > 1, "Check Denominator", "✅ OK") -> ✅ OK
... A22: TE_REN | B22: ReNew Power | C22: Tax Equity | D22: Renewables | E22: =_xlfn.XLOOKUP(A22, Entity_Master[Entity_ID], Entity_Master[Outstanding ($B)], "Missing ID") -> 7 | F22: =_xlfn.XLOOKUP(A22, Table5[Entity_ID], Table5[Entity_Denominator_Value ($B)], "Missing ID") -> 15 | G22: =E22/F22 -> 0.46666667 | H22: =_xlfn.XLOOKUP(A22, Table5[Entity_ID], Table5[Entity_GHG_Emissions (tCO2e)], "Missing ID") -> 315000 | I22: =G22*H22 -> 147000 | J22: =IF(Funded_Emissions[[#This Row],[Attribute_Factor (%)]]< 0.0001,"Check Units!","$ Units OK") -> $ Units OK | K22: =IF(AND(Funded_Emissions[[#This Row],[Entity_ID]]=_xlfn.XLOOKUP(Funded_Emissions[[#This Row],[Entity_ID]],Entity_Master[Entity_ID],Entity_Master[Entity_ID]), Funded_Emissions[[#This Row],[Entity_ID]]=_xlfn.XLOOKUP(Funded_Emissions[[#This Row],[Entity_ID]],Table5[Entity_ID],Table5[Entity_ID])),"✅ Match","❌ ID MISMATCH") -> ✅ Match | L22: =IF(Funded_Emissions[[#This Row],[Attribute_Factor (%)]] > 1, "Check Denominator", "✅ OK") -> ✅ OK
A23: Totals | H23: Estimated Financed Emissions = | I23: =SUM(I5:I22) -> 2.0576146e+08 | L23: =IF(Funded_Emissions[[#This Row],[Attribute_Factor (%)]] > 1, "Check Denominator", "✅ OK") -> ✅ OK
A27: Table 5 : Financed GHG Inventory for Total Committed Capital
A29: Entity Details | E29: Attribution Factor Calculation | H29: GHG Emissions Calculations | J29: Checks and Balances
A30: Entity_ID | B30: Legal_Entity_Name | C30: Asset_Class | D30: Sector | E30: Ref_Total_Committed ($B) | F30: Ref_Denominator ($B) | G30: Attribute_Factor (%) | H30: GHG Emissions (MT CO2e) | I30: Attributed_Emissions (MT CO2e) | J30: Check_Unit_Alert | K30: Check_Entity_Match | L30: Check_Attribute_Factor
A31: CB_DUK | B31: Duke Energy | C31: Corp. Bond | D31: Power Generation | E31: =_xlfn.XLOOKUP(A31, Entity_Master[Entity_ID], Entity_Master[Total_Committed ($B)], "Missing ID") -> 35 | F31: =_xlfn.XLOOKUP(A31, Table5[Entity_ID], Table5[Entity_Denominator_Value ($B)], "Missing ID") -> 181.08 | G31: =E31/F31 -> 0.19328474 | H31: =_xlfn.XLOOKUP(A31, Table5[Entity_ID], Table5[Entity_GHG_Emissions (tCO2e)], "Missing ID") -> 99108700 | I31: =G31*H31 -> 19156199 | J31: =IF(Committed_Emissions[[#This Row],[Attribute_Factor (%)]]< 0.0001,"Check Units!","$ Units OK") -> $ Units OK | K31: =IF(AND(Committed_Emissions[[#This Row],[Entity_ID]]=_xlfn.XLOOKUP(Committed_Emissions[[#This Row],[Entity_ID]],Entity_Master[Entity_ID],Entity_Master[Entity_ID]), Committed_Emissions[[#This Row],[Entity_ID]]=_xlfn.XLOOKUP(Committed_Emissions[[#This Row],[Entity_ID]],Table5[Entity_ID],Table5[Entity_ID])),"✅ Match","❌ ID MISMATCH") -> ✅ Match | L31: =IF(Committed_Emissions[[#This Row],[Attribute_Factor (%)]] > 1, "Check Denominator", "✅ OK") -> ✅ OK
A32: CB_MSFT | B32: Microsoft | C32: Corp. Bond | D32: IT | E32: =_xlfn.XLOOKUP(A32, Entity_Master[Entity_ID], Entity_Master[Total_Committed ($B)], "Missing ID") -> 50 | F32: =_xlfn.XLOOKUP(A32, Table5[Entity_ID], Table5[Entity_Denominator_Value ($B)], "Missing ID") -> 3713.28 | G32: =E32/F32 -> 0.013465184 | H32: =_xlfn.XLOOKUP(A32, Table5[Entity_ID], Table5[Entity_GHG_Emissions (tCO2e)], "Missing ID") -> 15543000 | I32: =G32*H32 -> 209289.36 | J32: =IF(Committed_Emissions[[#This Row],[Attribute_Factor (%)]]< 0.0001,"Check Units!","$ Units OK") -> $ Units OK | K32: =IF(AND(Committed_Emissions[[#This Row],[Entity_ID]]=_xlfn.XLOOKUP(Committed_Emissions[[#This Row],[Entity_ID]],Entity_Master[Entity_ID],Entity_Master[Entity_ID]), Committed_Emissions[[#This Row],[Entity_ID]]=_xlfn.XLOOKUP(Committed_Emissions[[#This Row],[Entity_ID]],Table5[Entity_ID],Table5[Entity_ID])),"✅ Match","❌ ID MISMATCH") -> ✅ Match | L32: =IF(Committed_Emissions[[#This Row],[Attribute_Factor (%)]] > 1, "Check Denominator", "✅ OK") -> ✅ OK
A33: CB_TOT | B33: TotalEnergies | C33: Corp. Bond | D33: Oil & Gas | E33: =_xlfn.XLOOKUP(A33, Entity_Master[Entity_ID], Entity_Master[Total_Committed ($B)], "Missing ID") -> 10 | F33: =_xlfn.XLOOKUP(A33, Table5[Entity_ID], Table5[Entity_Denominator_Value ($B)], "Missing ID") -> 201.3 | G33: =E33/F33 -> 0.049677099 | H33: =_xlfn.XLOOKUP(A33, Table5[Entity_ID], Table5[Entity_GHG_Emissions (tCO2e)], "Missing ID") -> 451040000 | I33: =G33*H33 -> 22406359 | J33: =IF(Committed_Emissions[[#This Row],[Attribute_Factor (%)]]< 0.0001,"Check Units!","$ Units OK") -> $ Units OK | K33: =IF(AND(Committed_Emissions[[#This Row],[Entity_ID]]=_xlfn.XLOOKUP(Committed_Emissions[[#This Row],[Entity_ID]],Entity_Master[Entity_ID],Entity_Master[Entity_ID]), Committed_Emissions[[#This Row],[Entity_ID]]=_xlfn.XLOOKUP(Committed_Emissions[[#This Row],[Entity_ID]],Table5[Entity_ID],Table5[Entity_ID])),"✅ Match","❌ ID MISMATCH") -> ✅ Match | L33: =IF(Committed_Emissions[[#This Row],[Attribute_Factor (%)]] > 1, "Check Denominator", "✅ OK") -> ✅ OK
A34: CB_TSN | B34: Tyson Foods | C34: Corp. Bond | D34: Agriculture | E34: =_xlfn.XLOOKUP(A34, Entity_Master[Entity_ID], Entity_Master[Total_Committed ($B)], "Missing ID") -> 20 | F34: =_xlfn.XLOOKUP(A34, Table5[Entity_ID], Table5[Entity_Denominator_Value ($B)], "Missing ID") -> 29 | G34: =E34/F34 -> 0.68965517 | H34: =_xlfn.XLOOKUP(A34, Table5[Entity_ID], Table5[Entity_GHG_Emissions (tCO2e)], "Missing ID") -> 65686757 | I34: =G34*H34 -> 45301212 | J34: =IF(Committed_Emissions[[#This Row],[Attribute_Factor (%)]]< 0.0001,"Check Units!","$ Units OK") -> $ Units OK | K34: =IF(AND(Committed_Emissions[[#This Row],[Entity_ID]]=_xlfn.XLOOKUP(Committed_Emissions[[#This Row],[Entity_ID]],Entity_Master[Entity_ID],Entity_Master[Entity_ID]), Committed_Emissions[[#This Row],[Entity_ID]]=_xlfn.XLOOKUP(Committed_Emissions[[#This Row],[Entity_ID]],Table5[Entity_ID],Table5[Entity_ID])),"✅ Match","❌ ID MISMATCH") -> ✅ Match | L34: =IF(Committed_Emissions[[#This Row],[Attribute_Factor (%)]] > 1, "Check Denominator", "✅ OK") -> ✅ OK
A35: CRE_Spire | B35: Spire | C35: Commercial Real Estate | D35: Real Estate | E35: =_xlfn.XLOOKUP(A35, Entity_Master[Entity_ID], Entity_Master[Total_Committed ($B)], "Missing ID") -> 0.3 | F35: =_xlfn.XLOOKUP(A35, Table5[Entity_ID], Table5[Entity_Denominator_Value ($B)], "Missing ID") -> 1.5 | G35: =E35/F35 -> 0.2 | H35: =_xlfn.XLOOKUP(A35, Table5[Entity_ID], Table5[Entity_GHG_Emissions (tCO2e)], "Missing ID") -> 9967 | I35: =G35*H35 -> 1993.4 | J35: =IF(Committed_Emissions[[#This Row],[Attribute_Factor (%)]]< 0.0001,"Check Units!","$ Units OK") -> $ Units OK | K35: =IF(AND(Committed_Emissions[[#This Row],[Entity_ID]]=_xlfn.XLOOKUP(Committed_Emissions[[#This Row],[Entity_ID]],Entity_Master[Entity_ID],Entity_Master[Entity_ID]), Committed_Emissions[[#This Row],[Entity_ID]]=_xlfn.XLOOKUP(Committed_Emissions[[#This Row],[Entity_ID]],Table5[Entity_ID],Table5[Entity_ID])),"✅ Match","❌ ID MISMATCH") -> ✅ Match | L35: =IF(Committed_Emissions[[#This Row],[Attribute_Factor (%)]] > 1, "Check Denominator", "✅ OK") -> ✅ OK
A36: Loan_ADANIPOWER | B36: Adani Power | C36: Business Loan | D36: Power Generation | E36: =_xlfn.XLOOKUP(A36, Entity_Master[Entity_ID], Entity_Master[Total_Committed ($B)], "Missing ID") -> 25 | F36: =_xlfn.XLOOKUP(A36, Table5[Entity_ID], Table5[Entity_Denominator_Value ($B)], "Missing ID") -> 40.06 | G36: =E36/F36 -> 0.6240639 | H36: =_xlfn.XLOOKUP(A36, Table5[Entity_ID], Table5[Entity_GHG_Emissions (tCO2e)], "Missing ID") -> 110561000 | I36: =G36*H36 -> 68997129 | J36: =IF(Committed_Emissions[[#This Row],[Attribute_Factor (%)]]< 0.0001,"Check Units!","$ Units OK") -> $ Units OK | K36: =IF(AND(Committed_Emissions[[#This Row],[Entity_ID]]=_xlfn.XLOOKUP(Committed_Emissions[[#This Row],[Entity_ID]],Entity_Master[Entity_ID],Entity_Master[Entity_ID]), Committed_Emissions[[#This Row],[Entity_ID]]=_xlfn.XLOOKUP(Committed_Emissions[[#This Row],[Entity_ID]],Table5[Entity_ID],Table5[Entity_ID])),"✅ Match","❌ ID MISMATCH") -> ✅ Match | L36: =IF(Committed_Emissions[[#This Row],[Attribute_Factor (%)]] > 1, "Check Denominator", "✅ OK") -> ✅ OK
A37: Loan_APO | B37: Apollo Hospitals | C37: Business Loan | D37: Healthcare | E37: =_xlfn.XLOOKUP(A37, Entity_Master[Entity_ID], Entity_Master[Total_Committed ($B)], "Missing ID") -> 4.5 | F37: =_xlfn.XLOOKUP(A37, Table5[Entity_ID], Table5[Entity_Denominator_Value ($B)], "Missing ID") -> 12.67 | G37: =E37/F37 -> 0.35516969 | H37: =_xlfn.XLOOKUP(A37, Table5[Entity_ID], Table5[Entity_GHG_Emissions (tCO2e)], "Missing ID") -> 231917.96 | I37: =G37*H37 -> 82370.232 | J37: =IF(Committed_Emissions[[#This Row],[Attribute_Factor (%)]]< 0.0001,"Check Units!","$ Units OK") -> $ Units OK | K37: =IF(AND(Committed_Emissions[[#This Row],[Entity_ID]]=_xlfn.XLOOKUP(Committed_Emissions[[#This Row],[Entity_ID]],Entity_Master[Entity_ID],Entity_Master[Entity_ID]), Committed_Emissions[[#This Row],[Entity_ID]]=_xlfn.XLOOKUP(Committed_Emissions[[#This Row],[Entity_ID]],Table5[Entity_ID],Table5[Entity_ID])),"✅ Match","❌ ID MISMATCH") -> ✅ Match | L37: =IF(Committed_Emissions[[#This Row],[Attribute_Factor (%)]] > 1, "Check Denominator", "✅ OK") -> ✅ OK
A38: Loan_CON | B38: Continental Resources | C38: Business Loan | D38: Oil & Gas | E38: =_xlfn.XLOOKUP(A38, Entity_Master[Entity_ID], Entity_Master[Total_Committed ($B)], "Missing ID") -> 10 | F38: =_xlfn.XLOOKUP(A38, Table5[Entity_ID], Table5[Entity_Denominator_Value ($B)], "Missing ID") -> 19.067 | G38: =E38/F38 -> 0.52446636 | H38: =_xlfn.XLOOKUP(A38, Table5[Entity_ID], Table5[Entity_GHG_Emissions (tCO2e)], "Missing ID") -> 10724842 | I38: =G38*H38 -> 5624818.9 | J38: =IF(Committed_Emissions[[#This Row],[Attribute_Factor (%)]]< 0.0001,"Check Units!","$ Units OK") -> $ Units OK | K38: =IF(AND(Committed_Emissions[[#This Row],[Entity_ID]]=_xlfn.XLOOKUP(Committed_Emissions[[#This Row],[Entity_ID]],Entity_Master[Entity_ID],Entity_Master[Entity_ID]), Committed_Emissions[[#This Row],[Entity_ID]]=_xlfn.XLOOKUP(Committed_Emissions[[#This Row],[Entity_ID]],Table5[Entity_ID],Table5[Entity_ID])),"✅ Match","❌ ID MISMATCH") -> ✅ Match | L38: =IF(Committed_Emissions[[#This Row],[Attribute_Factor (%)]] > 1, "Check Denominator", "✅ OK") -> ✅ OK
A39: Loan_ECO | B39: Eco-Startup Alpha | C39: Business Loan | D39: Renewables | E39: =_xlfn.XLOOKUP(A39, Entity_Master[Entity_ID], Entity_Master[Total_Committed ($B)], "Missing ID") -> 5 | F39: =_xlfn.XLOOKUP(A39, Table5[Entity_ID], Table5[Entity_Denominator_Value ($B)], "Missing ID") -> 15 | G39: =E39/F39 -> 0.33333333 | H39: =_xlfn.XLOOKUP(A39, Table5[Entity_ID], Table5[Entity_GHG_Emissions (tCO2e)], "Missing ID") -> 474000 | I39: =G39*H39 -> 158000 | J39: =IF(Committed_Emissions[[#This Row],[Attribute_Factor (%)]]< 0.0001,"Check Units!","$ Units OK") -> $ Units OK | K39: =IF(AND(Committed_Emissions[[#This Row],[Entity_ID]]=_xlfn.XLOOKUP(Committed_Emissions[[#This Row],[Entity_ID]],Entity_Master[Entity_ID],Entity_Master[Entity_ID]), Committed_Emissions[[#This Row],[Entity_ID]]=_xlfn.XLOOKUP(Committed_Emissions[[#This Row],[Entity_ID]],Table5[Entity_ID],Table5[Entity_ID])),"✅ Match","❌ ID MISMATCH") -> ✅ Match | L39: =IF(Committed_Emissions[[#This Row],[Attribute_Factor (%)]] > 1, "Check Denominator", "✅ OK") -> ✅ OK
A40: Loan_FAM | B40: Family Farm LLC | C40: Business Loan | D40: Agriculture | E40: =_xlfn.XLOOKUP(A40, Entity_Master[Entity_ID], Entity_Master[Total_Committed ($B)], "Missing ID") -> 5 | F40: =_xlfn.XLOOKUP(A40, Table5[Entity_ID], Table5[Entity_Denominator_Value ($B)], "Missing ID") -> 16 | G40: =E40/F40 -> 0.3125 | H40: =_xlfn.XLOOKUP(A40, Table5[Entity_ID], Table5[Entity_GHG_Emissions (tCO2e)], "Missing ID") -> 1225000 | I40: =G40*H40 -> 382812.5 | J40: =IF(Committed_Emissions[[#This Row],[Attribute_Factor (%)]]< 0.0001,"Check Units!","$ Units OK") -> $ Units OK | K40: =IF(AND(Committed_Emissions[[#This Row],[Entity_ID]]=_xlfn.XLOOKUP(Committed_Emissions[[#This Row],[Entity_ID]],Entity_Master[Entity_ID],Entity_Master[Entity_ID]), Committed_Emissions[[#This Row],[Entity_ID]]=_xlfn.XLOOKUP(Committed_Emissions[[#This Row],[Entity_ID]],Table5[Entity_ID],Table5[Entity_ID])),"✅ Match","❌ ID MISMATCH") -> ✅ Match | L40: =IF(Committed_Emissions[[#This Row],[Attribute_Factor (%)]] > 1, "Check Denominator", "✅ OK") -> ✅ OK
A41: Loan_HDB | B41: HDFC Bank | C41: Business Loan | D41: Financials | E41: =_xlfn.XLOOKUP(A41, Entity_Master[Entity_ID], Entity_Master[Total_Committed ($B)], "Missing ID") -> 35 | F41: =_xlfn.XLOOKUP(A41, Table5[Entity_ID], Table5[Entity_Denominator_Value ($B)], "Missing ID") -> 232.26 | G41: =E41/F41 -> 0.15069319 | H41: =_xlfn.XLOOKUP(A41, Table5[Entity_ID], Table5[Entity_GHG_Emissions (tCO2e)], "Missing ID") -> 593187.45 | I41: =G41*H41 -> 89389.308 | J41: =IF(Committed_Emissions[[#This Row],[Attribute_Factor (%)]]< 0.0001,"Check Units!","$ Units OK") -> $ Units OK | K41: =IF(AND(Committed_Emissions[[#This Row],[Entity_ID]]=_xlfn.XLOOKUP(Committed_Emissions[[#This Row],[Entity_ID]],Entity_Master[Entity_ID],Entity_Master[Entity_ID]), Committed_Emissions[[#This Row],[Entity_ID]]=_xlfn.XLOOKUP(Committed_Emissions[[#This Row],[Entity_ID]],Table5[Entity_ID],Table5[Entity_ID])),"✅ Match","❌ ID MISMATCH") -> ✅ Match | L41: =IF(Committed_Emissions[[#This Row],[Attribute_Factor (%)]] > 1, "Check Denominator", "✅ OK") -> ✅ OK
A42: Loan_TAT | B42: Tata Steel | C42: Business Loan | D42: Industrials | E42: =_xlfn.XLOOKUP(A42, Entity_Master[Entity_ID], Entity_Master[Total_Committed ($B)], "Missing ID") -> 20 | F42: =_xlfn.XLOOKUP(A42, Table5[Entity_ID], Table5[Entity_Denominator_Value ($B)], "Missing ID") -> 35.63 | G42: =E42/F42 -> 0.56132473 | H42: =_xlfn.XLOOKUP(A42, Table5[Entity_ID], Table5[Entity_GHG_Emissions (tCO2e)], "Missing ID") -> 92100000 | I42: =G42*H42 -> 51698007 | J42: =IF(Committed_Emissions[[#This Row],[Attribute_Factor (%)]]< 0.0001,"Check Units!","$ Units OK") -> $ Units OK | K42: =IF(AND(Committed_Emissions[[#This Row],[Entity_ID]]=_xlfn.XLOOKUP(Committed_Emissions[[#This Row],[Entity_ID]],Entity_Master[Entity_ID],Entity_Master[Entity_ID]), Committed_Emissions[[#This Row],[Entity_ID]]=_xlfn.XLOOKUP(Committed_Emissions[[#This Row],[Entity_ID]],Table5[Entity_ID],Table5[Entity_ID])),"✅ Match","❌ ID MISMATCH") -> ✅ Match | L42: =IF(Committed_Emissions[[#This Row],[Attribute_Factor (%)]] > 1, "Check Denominator", "✅ OK") -> ✅ OK
... A48: TE_REN | B48: ReNew Power | C48: Tax Equity | D48: Renewables | E48: =_xlfn.XLOOKUP(A48, Entity_Master[Entity_ID], Entity_Master[Total_Committed ($B)], "Missing ID") -> 10 | F48: =_xlfn.XLOOKUP(A48, Table5[Entity_ID], Table5[Entity_Denominator_Value ($B)], "Missing ID") -> 15 | G48: =E48/F48 -> 0.66666667 | H48: =_xlfn.XLOOKUP(A48, Table5[Entity_ID], Table5[Entity_GHG_Emissions (tCO2e)], "Missing ID") -> 315000 | I48: =G48*H48 -> 210000 | J48: =IF(Committed_Emissions[[#This Row],[Attribute_Factor (%)]]< 0.0001,"Check Units!","$ Units OK") -> $ Units OK | K48: =IF(AND(Committed_Emissions[[#This Row],[Entity_ID]]=_xlfn.XLOOKUP(Committed_Emissions[[#This Row],[Entity_ID]],Entity_Master[Entity_ID],Entity_Master[Entity_ID]), Committed_Emissions[[#This Row],[Entity_ID]]=_xlfn.XLOOKUP(Committed_Emissions[[#This Row],[Entity_ID]],Table5[Entity_ID],Table5[Entity_ID])),"✅ Match","❌ ID MISMATCH") -> ✅ Match | L48: =IF(Committed_Emissions[[#This Row],[Attribute_Factor (%)]] > 1, "Check Denominator", "✅ OK") -> ✅ OK
A49: Totals | H49: Estimated Financed Emissions = | I49: =SUM(I31:I48) -> 2.4848115e+08 | L49: =IF(Committed_Emissions[[#This Row],[Attribute_Factor (%)]] > 1, "Check Denominator", "✅ OK") -> ✅ OK

Sheet 06_Technical_Appendix
A1: Table : Emission Calculations from Revenue
A3: Entity_ID (CFI_Ticker) | B3: Legal_Entity_Name | C3: Asset_Class | D3: Sector | E3: Revenue $B | F3: EEIO Factor | G3: EEIO Category | H3: Calculated Emissions tCO2e/USD | I3: Source | J3: Check for Intensity factor
A4: Loan_APO | B4: Apollo Hospitals | C4: Business Loan | D4: Healthcare | E4: =757901844.9/1000000000 -> 0.75790184 | F4: 0.306 | G4: Hospitals | H4: =Table6[[#This Row],[Revenue $B]]*Table6[[#This Row],[EEIO Factor]]*1000000000/1000 -> 231917.96 | I4: CEDA Database for EEIO factor applied to revenue | J4: =IF(Table6[[#This Row],[EEIO Factor]] > 1.5, "High Intensity: Verify Units", "Normal Range") -> Normal Range
A5: Loan_CON | B5: Continental Resources | C5: Business Loan | D5: Oil & Gas | E5: =7693574000/1000000000 -> 7.693574 | F5: 1.394 | G5: Oil & Gas Extraction | H5: =Table6[[#This Row],[Revenue $B]]*Table6[[#This Row],[EEIO Factor]]*1000000000/1000 -> 10724842 | I5: CEDA Database for EEIO factor applied to revenue | J5: =IF(Table6[[#This Row],[EEIO Factor]] > 1.5, "High Intensity: Verify Units", "Normal Range") -> Normal Range
A6: Loan_FAM | B6: Family Farm LLC | C6: Business Loan | D6: Agriculture | E6: =3500000000/1000000000 -> 3.5 | F6: 0.35 | H6: =Table6[[#This Row],[Revenue $B]]*Table6[[#This Row],[EEIO Factor]]*1000000000/1000 -> 1225000 | I6: CEDA Database for EEIO factor applied to revenue | J6: =IF(Table6[[#This Row],[EEIO Factor]] > 1.5, "High Intensity: Verify Units", "Normal Range") -> Normal Range
A10: Table : Emissions Calculations from Product value
A12: Entity_ID (CFI_Ticker) | B12: Legal_Entity_Name | C12: Asset_Class | D12: Sector | E12: Product Type | F12: Product Type Revenue (USD) | G12: Emission Factors | H12: Unit | I12: Emissions | J12: Source
A13: CB_TSN | B13: Tyson Foods | C13: Corp. Bond | D13: Agriculture | E13: Beef | F13: 21623000000 | G13: 1.792 | H13: kgCo2e/USD | I13: =F13*G13/1000 -> 38748416 | J13: CEDA Database for EEIO factor applied to revenue
A14: CB_TSN | B14: Tyson Foods | C14: Corp. Bond | D14: Agriculture | E14: Pork | F14: 5781000000 | G14: 1.792 | H14: kgCo2e/USD | I14: =F14*G14/1000 -> 10359552 | J14: CEDA Database for EEIO factor applied to revenue
A15: CB_TSN | B15: Tyson Foods | C15: Corp. Bond | D15: Agriculture | E15: Chicken | F15: 16873000000 | G15: 0.663 | H15: kgCo2e/USD | I15: =F15*G15/1000 -> 11186799 | J15: CEDA Database for EEIO factor applied to revenue
A16: CB_TSN | B16: Tyson Foods | C16: Corp. Bond | D16: Agriculture | E16: Prepared Food | F16: 9930000000 | G16: 0.543 | H16: kgCo2e/USD | I16: =F16*G16/1000 -> 5391990 | J16: CEDA Database for EEIO factor applied to revenue
A17: Total | F17: =SUM(F13:F16) -> 54207000000 | I17: =SUM(I13:I16) -> 65686757

Sheet 07_Reconciliation
